<?xml version="1.0" ?>
<!-- =================================================================================== -->
<!-- |    This document was autogenerated by xacro from hydra3.urdf.xacro              | -->
<!-- |    EDITING THIS FILE BY HAND IS NOT RECOMMENDED                                 | -->
<!-- =================================================================================== -->
<robot name="hydra3" xmlns:xacro="http://www.ros.org/wiki/xacro">
  <link name="link1">
    <visual>
      <origin rpy="0 0 3.14159265359" xyz="0 0 0"/>
      <geometry>
        <mesh filename="package://aerial_robot_model/urdf/hydra3/mesh/hydra_link1.stl" scale=".001 .001 .001"/>
      </geometry>
      <material name="gray">
        <color rgba="0.75 .5 .2 1"/>
      </material>
    </visual>
  </link>
  <joint name="joint1" type="revolute">
    <limit effort="100.0" lower="-1.57" upper="1.57" velocity="0.5"/>
    <parent link="link1"/>
    <child link="joint1"/>
    <origin rpy="0 0 0" xyz="-0.22 0 0"/>
    <axis xyz="0 0 1"/>
  </joint>
  <link name="joint1">  </link>
  <joint name="joint1_link2" type="fixed">
    <parent link="joint1"/>
    <child link="link2"/>
    <origin rpy="0 0 0" xyz="-0.22 0 0"/>
  </joint>
  <link name="link2">
    <visual>
      <origin rpy="0 0 3.14159265359" xyz="0 0 0"/>
      <geometry>
        <mesh filename="package://aerial_robot_model/urdf/hydra3/mesh/hydra_link2.stl" scale=".001 .001 .001"/>
      </geometry>
      <material name="gray">
        <color rgba="0.75 .5 .2 1"/>
      </material>
    </visual>
  </link>
  <joint name="joint2" type="revolute">
    <limit effort="100.0" lower="-1.57" upper="1.57" velocity="0.5"/>
    <parent link="link2"/>
    <child link="joint2"/>
    <origin rpy="0 0 0" xyz="-0.22 0 0"/>
    <axis xyz="0 0 1"/>
  </joint>
  <link name="joint2">  </link>
  <joint name="joint2_link3" type="fixed">
    <parent link="joint2"/>
    <child link="link3"/>
    <origin rpy="0 0 0" xyz="-0.22 0 0"/>
  </joint>
  <link name="link3">
    <visual>
      <origin rpy="0 0 3.14159265359" xyz="0 0 0"/>
      <geometry>
        <mesh filename="package://aerial_robot_model/urdf/hydra3/mesh/hydra_link3.stl" scale=".001 .001 .001"/>
      </geometry>
      <material name="gray">
        <color rgba="0.75 .5 .2 1"/>
      </material>
    </visual>
  </link>
  <joint name="joint3" type="revolute">
    <limit effort="100.0" lower="-1.57" upper="1.57" velocity="0.5"/>
    <parent link="link3"/>
    <child link="joint3"/>
    <origin rpy="0 0 0" xyz="-0.22 0 0"/>
    <axis xyz="0 0 1"/>
  </joint>
  <link name="joint3">  </link>
  <joint name="joint3_link4" type="fixed">
    <parent link="joint3"/>
    <child link="link4"/>
    <origin rpy="0 0 0" xyz="-0.22 0 0"/>
  </joint>
  <link name="link4">
    <visual>
      <origin rpy="0 0 3.14159265359" xyz="0 0 0"/>
      <geometry>
        <mesh filename="package://aerial_robot_model/urdf/hydra3/mesh/hydra_link4.stl" scale=".001 .001 .001"/>
      </geometry>
      <material name="gray">
        <color rgba="0.75 .5 .2 1"/>
      </material>
    </visual>
  </link>
</robot>

