<?xml version="1.0" ?>
<!-- =================================================================================== -->
<!-- |    This document was autogenerated by xacro from hydra3.urdf.xacro              | -->
<!-- |    EDITING THIS FILE BY HAND IS NOT RECOMMENDED                                 | -->
<!-- =================================================================================== -->
<robot name="hydra3" xmlns:xacro="http://www.ros.org/wiki/xacro">
  <link name="link1">
    <collision>
      <origin rpy="0 0 0" xyz="0 0 0"/>
      <geometry>
        <cylinder length="0.1" radius="0.155"/>
      </geometry>
    </collision>
    <visual>
      <origin rpy="0 0 3.14159265359" xyz="0 0 0"/>
      <geometry>
        <mesh filename="package://aerial_robot_model/urdf/hydra3/mesh/hydra_link1.stl" scale=".001 .001 .001"/>
      </geometry>
      <material name="color">
        <color rgba="0.75 .5 .2 1"/>
      </material>
    </visual>
    <inertial>
      <origin rpy="0 0 0" xyz="0 0 0"/>
      <mass value="0.5"/>
      <inertia ixx="0.1" ixy="0.0" ixz="0.0" iyy="0.01" iyz="0.0" izz="0.11"/>
    </inertial>
  </link>

  <joint name="joint1" type="revolute">
    <limit effort="100.0" lower="-1.57" upper="1.57" velocity="0.5"/>
    <parent link="link1"/>
    <child link="joint1"/>
    <origin rpy="0 0 0" xyz="-0.22 0 0"/>
    <axis xyz="0 0 1"/>
    <dynamics damping="0.8"/>
  </joint>
  <link name="joint1">
<!--
    <collision>
      <origin rpy="0 0 0" xyz="0 0 0"/>
      <geometry>
        <cylinder length="0.05" radius="0.02"/>
      </geometry>
    </collision>
    <visual>
      <origin rpy="0 0 0" xyz="0 0 0"/>
      <geometry>
        <cylinder length="0.001" radius="0.001"/>
      </geometry>
      <material name="color">
        <color rgba="0.75 .5 .2 1"/>
      </material>
    </visual>
    <inertial>
      <origin rpy="0 0 0" xyz="0 0 0"/>
      <mass value="0.1"/>
      <inertia ixx="0.00005" ixy="0.0" ixz="0.0" iyy="0.00005" iyz="0.0" izz="0.0001"/>
    </inertial>
-->
  </link>

  <joint name="joint1_link2" type="fixed">
    <parent link="joint1"/>
    <child link="link2"/>
    <origin rpy="0 0 0" xyz="-0.22 0 0"/>
  </joint>


  <link name="link2">
    <collision>
      <origin rpy="0 0 0" xyz="0 0 0"/>
      <geometry>
        <cylinder length="0.1" radius="0.155"/>
      </geometry>
    </collision>
    <visual>
      <origin rpy="0 0  3.14159265359" xyz="0 0 0"/>
      <geometry>
        <mesh filename="package://aerial_robot_model/urdf/hydra3/mesh/hydra_link4.stl" scale=".001 .001 .001"/> 
      </geometry>
      <material name="color">
        <color rgba="0.75 .5 .2 1"/>
      </material>
    </visual>
    <inertial>
      <origin rpy="0 0 0" xyz="0 0 0 "/>
      <mass value="0.5"/>
      <inertia ixx="0.1" ixy="0.0" ixz="0.0" iyy="0.01" iyz="0.0" izz="0.11"/>
    </inertial>
  </link>

 <!-- ros_control plugin -->
<!--
  <gazebo>
    <plugin name="gazebo_ros_control" filename="libgazebo_ros_control.so">
      <robotNamespace>/hydra3</robotNamespace>
      <robotSimType>gazebo_ros_control/DefaultRobotHWSim</robotSimType>
    </plugin>
  </gazebo>
-->

 <transmission name="tran1">
    <type>transmission_interface/SimpleTransmission</type>
    <joint name="joint1">
      <hardwareInterface>EffortJointInterface</hardwareInterface>
    </joint>
    <actuator name="motor1">
      <hardwareInterface>EffortJointInterface</hardwareInterface>
      <mechanicalReduction>1</mechanicalReduction>
    </actuator>
 </transmission>


  <!-- Link1 -->
  <gazebo reference="link1">
    <material>Gazebo/Orange</material>
  </gazebo>

  <!-- Joint1 -->
  <gazebo reference="joint1">
    <material>Gazebo/Orange</material>
  </gazebo>

  <!-- Link2 -->
  <gazebo reference="link2">
    <material>Gazebo/Black</material>
  </gazebo>
</robot>

