<mujoco model="kxr_flight_unit">
  <compiler coordinate="local" convexhull="false" angle="radian" meshdir="mesh/kxr_flight_unit"/>
  <option timestep="0.005" gravity="0 0 -9.81" density="1" viscosity="1e-3" collision="all"/>
  <asset>
    <mesh file="kxr_flight_unit_base_link.STL" name="base_link_mesh" scale="0.001 0.001 0.001"/>
    <mesh file="thrust_link_left.STL" name="thrust_link_left_mesh" scale="0.001 0.001 0.001"/>
    <mesh file="thrust_link_right.STL" name="thrust_link_right_mesh" scale="0.001 0.001 0.001"/>
  </asset>
  <worldbody>
    <geom name="floor" pos="0 0 0" size="2 2 .2" type="plane"  conaffinity="1" rgba="1 1 1 1" condim="3"/>
    <body name="u0_base_link" pos="0 0 1.25" >
      <geom mesh="base_link_mesh" type="mesh" rgba="0.9 0.9 0.9 1.0" contype="1" conaffinity="0"/>
      <inertial pos="-0.000741 0.000111 -0.034417" mass="0.942442" fullinertia="0.015351 0.002766 0.013177 0.000002 0.000024 0.000002"/>
      <joint name="root" type="free" damping="0" armature="0" pos="0 0 0" />
      <site name="u0" pos="0.0 0.0 0.0" quat="1.0 0.0 0.0 0.0"/>

      <body name="u0_thrust0_link" pos="0.0 0.154 0.051" quat = "1. 0. 0. 0.">
        <geom mesh="thrust_link_left_mesh" type="mesh" rgba="0.1 0.1 0.1 1.0" contype="1" conaffinity="0"/>
        <inertial pos="0.0 0.078713 0.005683" mass="0.250950" fullinertia="0.001920 0.000249 0.001997 0.0000000 0.0000000 0.000131"/>
        <joint name="u0_thrust0_joint" limited="true" type="hinge" pos="0 0 0" axis="0 1 0" range="-180 180" damping="5" stiffness="0" armature="0.002" frictionloss="0.03" />

        <site name="u0_motor0" pos="0.0 0.080736 0.007697" quat="0.99891668 0.04653461 0.0 0.0"/>
        <site type="box" size="0.005 0.005 0.05" pos="0.0 0.081102 0.03707" quat="0.99891668 0.04653461 0.0 0.0" rgba="1.0 0.7 0.0 1"/>
      </body>
      <body name="u0_thrust1_link" pos="0.0 -0.154 0.051" quat = "0. 0. 0. 1.0">
        <geom mesh="thrust_link_right_mesh" type="mesh" rgba="0.1 0.1 0.1 1.0" contype="1" conaffinity="0"/>
        <inertial pos="0.0 0.078713 0.005683" mass="0.250950" fullinertia="0.001920 0.000249 0.001997 0.0000000 0.0000000 0.000131"/>
        <joint name="u0_thrust1_joint" limited="true" type="hinge" pos="0 0 0" axis="0 -1 0" range="-180 180" damping="5" stiffness="0" armature="0.002" frictionloss="0.03" />
        <site name="u0_motor1" pos="0.0 0.080736 0.007697" quat="0.99891668 0.04653461 0.0 0.0"/>
        <site type="box" size="0.005 0.005 0.05" pos="0.0 0.081102 0.03707" quat="0.99891668 0.04653461 0.0 0.0" rgba="1.0 0.7 0.0 1"/>
      </body>

      <!-- Visualization of the coordinate frame -->
      <site name="qcX" type="box" pos="0.1 0.0 0.0" size="0.1 0.005 0.005"  quat = " 1.000  0.0  0.0    0."     rgba="1 0 0 1" />
      <site name="qcY" type="box" pos="0.0 0.1 0.0" size="0.1 0.005 0.005"  quat = " 0.707  0.0  0.0    0.707"  rgba="0 1 0 1" />
      <site name="qcZ" type="box" pos="0.0 0.0 0.1" size="0.1 0.005 0.005"  quat = "-0.707  0.0  0.707  0."     rgba="0 0 1 1" />
    </body>
  </worldbody>
  <actuator>
    <motor name="u0_thrust0" ctrllimited="true" ctrlrange="0.0 20.0" gear="0  0. 1. 0. 0. -0.01" site="u0_motor0"/>
    <motor name="u0_thrust1" ctrllimited="true" ctrlrange="0.0 20.0" gear="0  0. 1. 0. 0.  0.01" site="u0_motor1"/>
    <position name="u0_thrust0-p" kp="40" joint="u0_thrust0_joint"/>
    <position name="u0_thrust1-p" kp="40" joint="u0_thrust1_joint"/>

  </actuator>
</mujoco>
