<?xml version="1.0"?>
<robot
    xmlns:xacro="http://www.ros.org/wiki/xacro" name="birotor_link" >

  <xacro:macro name="birotor_center_link" params="child1 child2">
    ## link
    #### root link (vitrual) ####
    <link name="root">
      <inertial>
        <origin xyz="0 0 0" rpy="0 0 0"/>
        <mass value="0.00001"/>
        <inertia
            ixx="0.000001" iyy="0.000001" izz="0.000001"
            ixy="0.000000" ixz="0.000000" iyz="0.000000"/>
      </inertial>
    </link>

    #### base link ####
    <link name="base_link">
      <inertial>
        <origin xyz="0 0 -0.034417" rpy="0 0 0"/>
        <mass value="0.942442"/>
        <inertia
            ixx="0.015351" iyy="0.002766" izz="0.013177"
            ixy="-0.000002" ixz="-0.000024" iyz="0.000002"/>
      </inertial>
      <visual>
        <geometry>
          <mesh filename="package://birotor/urdf/mesh/kxr_flight_unit_base_link.dae" scale="0.001 0.001 0.001"/>
          <origin xyz="0 0 0" rpy="0 0 0"/>
        </geometry>
      </visual>
      <collision>
        <origin xyz="0 0 0" rpy="0 0 0"/>
        <geometry>
          <box size="0.1 0.3 0.21"/>
        </geometry>
      </collision>
    </link>
    <xacro:damping_factor link="base_link"/>

    #### rotor coord link (virtual)####
    <link name="rotor_coord${child1}">
      <inertial>
        <origin xyz="0 0 0" rpy="0 0 0"/>
        <mass value="0.00001"/>
        <inertia
            ixx="0.000001" iyy="0.000001" izz="0.000001"
            ixy="0.000000" ixz="0.000000" iyz="0.000000"/>
      </inertial>
    </link>

    <link name="rotor_coord${child2}">
      <inertial>
        <origin xyz="0 0 0" rpy="0 0 0"/>
        <mass value="0.00001"/>
        <inertia
            ixx="0.000001" iyy="0.000001" izz="0.000001"
            ixy="0.000000" ixz="0.000000" iyz="0.000000"/>
      </inertial>
    </link>

    #### fcu frame ####
    <link name="fc">
      <inertial>
        <origin xyz="0 0 0" rpy="0 0 0"/>
        <mass value="0.00001"/>
        <inertia
            ixx="0.000001" iyy="0.000001" izz="0.000001"
            ixy="0.000000" ixz="0.000000" iyz="0.000000"/>
      </inertial>
    </link>

    ## joints ##
    #### fixed frames (virtual) ####
    <joint name="root_joint" type="fixed">
      <parent link="root"/>
      <child link="base_link"/>
      <origin xyz="0 0 0" rpy="0 0 0"/>
      <axis xyz="0 0 1"/>
    </joint>

    <joint name="fc_joint" type="fixed">
      <parent link="base_link"/>
      <child link="fc"/>
      <origin xyz="0 0 0" rpy="0 0 0"/>
      <axis xyz="0 0 1"/>
    </joint>

    #### rotor coord link joint (virtual) ####
    <joint name="rotor_coord_joint${child1}" type="fixed">
      <parent link="base_link" />
      <child link="rotor_coord${child1}"/>
      <origin xyz="0 0.154 0.051" rpy="0 0 ${pi/2}"/>
      <axis xyz="0 0 1"/>
    </joint>

    <joint name="rotor_coord_joint${child2}" type="fixed">
      <parent link="base_link"/>
      <child link="rotor_coord${child2}"/>
      <origin xyz="0 -0.154 0.051" rpy="0 0 ${-pi/2}"/>
      <axis xyz="0 0 1"/>
    </joint>

    #### gimbal link joint ####
    <joint name="gimbal${child1}" type="revolute">
      <limit effort="6.6" lower="-1.57" upper="1.57" velocity="3.0"/>
      <parent link="rotor_coord${child1}"/>
      <child link="gimbal_link${child1}"/>
      <origin xyz="0 0 0" rpy="0 0 0"/>
      <axis xyz="1 0 0"/>
      <dynamics damping="0.8" friction="0.0"/>
    </joint>

    <joint name="gimbal${child2}" type="revolute">
      <limit effort="6.6" lower="-1.57" upper="1.57" velocity="3.0"/>
      <parent link="rotor_coord${child2}"/>
      <child link="gimbal_link${child2}"/>
      <origin xyz="0 0 0" rpy="0 0 0"/>
      <axis xyz="1 0 0"/>
      <dynamics damping="0.8" friction="0.0"/>
    </joint>

    ## hardware interface ##
    <transmission name="joint_tran${child1}">
      <type>transmission_interface/SimpleTransmission</type>
      <joint name="gimbal${child1}">
        <hardwareInterface>hardware_interface/EffortJointInterface</hardwareInterface>
      </joint>
      <actuator name="servo${child1}">
        <hardwareInterface>hardware_interface/EffortJointInterface</hardwareInterface>
        <mechanicalReduction>1</mechanicalReduction>
      </actuator>
    </transmission>

    <transmission name="joint_tran${child2}">
      <type>transmission_interface/SimpleTransmission</type>
      <joint name="gimbal${child2}">
        <hardwareInterface>hardware_interface/EffortJointInterface</hardwareInterface>
      </joint>
      <actuator name="servo${child2}">
        <hardwareInterface>hardware_interface/EffortJointInterface</hardwareInterface>
        <mechanicalReduction>1</mechanicalReduction>
      </actuator>
    </transmission>

    <xacro:friction self="base_link"/>
  </xacro:macro>

  <xacro:macro name="birotor_thrust_link" params="self rotor_direction">
    ## link
    #### rotor link  ####
    <link name="gimbal_link${self}">
      <inertial>
        <origin xyz="0.0835 0 0" rpy="0 0 0"/>
        <mass value="0.250950"/>
        <inertia
            ixx="0.001920" iyy="0.000249" izz="0.013177"
            ixy="0.000002" ixz="-0.000024" iyz="0.000002"/>
      </inertial>
      <visual>
        <origin xyz="0 0 0" rpy="0 0 ${-pi/2}"/>
        <geometry>
          <mesh filename="package://birotor/urdf/mesh/thrust_link_left_straight.dae" scale="0.001 0.001 0.001"/>
        </geometry>
      </visual>
      <collision>
        <origin xyz="0.0835 0 0" rpy="0 0 0"/>
        <geometry>
          <cylinder radius="0.1" length="0.1"/>
        </geometry>
      </collision>
    </link>
    <xacro:damping_factor link="gimbal_link${self}"/>

    #### rotor parent link (virtual) ####
    <link name="rotor_parent${self}">
      <inertial>
        <origin xyz="0 0 0" rpy="0 0 0"/>
        <mass value="0.00001"/>
        <inertia
            ixx="0.000001" iyy="0.000001" izz="0.000001"
            ixy="0.000000" ixz="0.000000" iyz="0.000000"/>
      </inertial>
    </link>

    #### thrust link (virtual) ####
    <link name="thrust${self}">
      <inertial>
        <origin xyz="0 0 0" rpy="0 0 0"/>
        <mass value="0.00001"/>
        <inertia
            ixx="0.000001" iyy="0.000001" izz="0.000001"
            ixy="0.000000" ixz="0.000000" iyz="0.000000"/>
      </inertial>
    </link>
    <xacro:damping_factor link="thrust${self}"/>

    ## joints ##
    #### rotor parent link joint (virtual) ####
    <joint name="rotor_parent_link_joint${self}" type="fixed">
      <parent link="gimbal_link${self}"/>
      <child link="rotor_parent${self}"/>
      <origin xyz="0.0835 0 0" rpy="0 0 0"/>
      <axis xyz="0 0 1"/>
    </joint>

    #### rotor joint (virtual) ####
    <joint name="rotor${self}" type="continuous">
      <limit effort="100.0" lower="${min_force}" upper="${max_force}" velocity="0.5"/>
      <parent link="rotor_parent${self}"/>
      <child link="thrust${self}"/>
      <origin rpy="0 0 0" xyz="0 0 0"/>
      <axis xyz="0 0 ${rotor_direction}"/>
    </joint>

    #### hardware interface ####
    <transmission name="rotor_tran${self}">
      <type>transmission_interface/SimpleTransmission</type>
      <joint name="rotor${self}">
        <hardwareInterface>RotorInterface</hardwareInterface>
      </joint>
      <actuator name="rotor_actuator${self}">
        <hardwareInterface>RotorInterface</hardwareInterface>
        <mechanicalReduction>1</mechanicalReduction>
      </actuator>
    </transmission>

  </xacro:macro>
</robot>
