<?xml version="1.0"?>
<robot
    xmlns:xacro="http://www.ros.org/wiki/xacro" name="hydrus3_link" >

  <!-- D-H kai description(different from prof.nakamura) -->

  <xacro:macro name="hydrus3_link" params="self child head tail imu">

    <!-- link -->
    <link name="link${self}">
      <!-- inertial -->
      <inertial>
        <origin xyz="${link_length*.5} 0 0" rpy="0 0 0"/>
        <xacro:link_inertial head = "${head}" tail = "${tail}" imu = "${imu}" />
      </inertial>

      <!-- visual & collisiont -->
      <xacro:if value="${head}">
        <xacro:link_model self="1" />
      </xacro:if>
      <xacro:unless value="${head}">
        <xacro:if value="${imu}">
          <xacro:link_model self="2" />
        </xacro:if>
        <xacro:unless value="${imu}">
          <xacro:if value="${tail}">
            <xacro:link_model self="4" />
          </xacro:if>
          <xacro:unless value="${tail}">
            <xacro:link_model self="3" />
          </xacro:unless>
        </xacro:unless>
      </xacro:unless>
    </link>
    <xacro:damping_factor link ="link${self}"/>

    <!-- link center(virtual) -->
    <!-- not good -->
    <joint name="center${self}" type="fixed">
      <parent link="link${self}"/>
      <child link="link${self}_center"/>
      <origin rpy="0 0 0" xyz="${link_length*.5} 0 0"/>
      <axis xyz="0 0 1"/>
    </joint>

    <link name="link${self}_center">
      <!-- visual & collisiont -->
      <inertial>
        <origin xyz="0 0 0" rpy="0 0 0"/>
        <mass value="0.001"/>
        <inertia
            ixx="0.00000001" ixy="0.0" ixz="0.0"
            iyy="0.00000001" iyz="0.0"
            izz="0.00000002"/>
      </inertial>
    </link>
    <xacro:damping_factor link ="link${self}_center"/>

    <!-- rotor -->
    <joint name="rotor${self}" type="continuous">
      <limit effort="100.0" lower="0" upper="${max_force}" velocity="0.5"/> <!-- force range -->
      <parent link="link${self}"/>
      <child link="propeller${self}"/>
      <origin rpy="0 0 0" xyz="${link_length*.5} 0 0"/>
      <axis xyz="0 0 1"/>
    </joint>

    <link name="propeller${self}">
      <!-- visual & collisiont -->
      <inertial>
        <origin xyz="0 0 0" rpy="0 0 0"/>
        <mass value="${rotor_mass}"/>
        <inertia
            ixx="${rotor_mass * .25 * rotor_radius * rotor_radius}" ixy="0.0" ixz="0.0"
            iyy="${rotor_mass * .25 * rotor_radius * rotor_radius}" iyz="0.0"
            izz="${rotor_mass * .5 * rotor_radius * rotor_radius}"/>
      </inertial>
    </link>
    <xacro:damping_factor link ="propeller${self}"/>

    <!-- joint -->>
    <xacro:unless value="${tail}">

      <joint name="joint${self}" type="revolute">
        <limit effort="3.1" lower="-1.57" upper="1.57" velocity="0.5"/>
        <parent link="link${self}"/>
        <child link="link${child}"/>
        <origin rpy="0 0 0" xyz="${link_length} 0 0"/>
        <axis xyz="0 0 1"/>
        <dynamics damping="0.8" friction="0.05"/>
      </joint>
    </xacro:unless> <!-- var_tail -->

    <!-- hardware interface -->
    <xacro:unless value="${tail}">
      <transmission name="joint_tran${self}">
        <type>transmission_interface/SimpleTransmission</type>
        <joint name="joint${self}">
          <!-- TODO: effort is torque, maybe position is enough -->
          <hardwareInterface>hardware_interface/EffortJointInterface</hardwareInterface>
        </joint>
        <actuator name="servo{self}">
          <!-- TODO: effort is torque, maybe position is enough -->
          <hardwareInterface>hardware_interface/EffortJointInterface</hardwareInterface>
          <mechanicalReduction>1</mechanicalReduction>
        </actuator>
      </transmission>
    </xacro:unless> <!-- var_tail -->

    <transmission name="rotor_tran${self}">
      <type>transmission_interface/SimpleTransmission</type>
      <joint name="rotor${self}">
        <!-- TODO: effort is torque, maybe position is enough -->
        <hardwareInterface>RotorInterface</hardwareInterface>
      </joint>
      <actuator name="rotor${self}">
        <!-- TODO: effort is torque, maybe position is enough -->
        <hardwareInterface>RotorInterface</hardwareInterface>
        <mechanicalReduction>1</mechanicalReduction>
      </actuator>
    </transmission>

    <xacro:friction self ="${self}"/>

  </xacro:macro>

</robot>
