<?xml version="1.0"?>
<robot
    xmlns:xacro="http://www.ros.org/wiki/xacro" name="rolling_link" >
  <xacro:property name="rotor_offset" value="0.05" />
  <xacro:property name="rotor_pos" value="0.1935"/> #default = 0.1935

  <xacro:macro name="rolling_module" params="self child baselink rotor_direction">
    ### link ###
    <link name="link${self}">
      <inertial>
        <origin xyz="0.27537173 -0.03961308 -0.00327255" rpy="0 0 0" />
        <mass value="0.49664453" />
        <inertia
            ixx="0.00358710" iyy="0.02132702" izz="0.02325324"
            ixy="0.00006483" ixz="0.00207127" iyz="0.00033016" />
      </inertial>
      <visual>
        <origin rpy="0 0 0" xyz="0 0 0"/>
        <geometry>
          <mesh filename="package://rolling/urdf/shelled/mesh/link.STL" scale="0.001 0.001 0.001"/>
        </geometry>
        <xacro:glay/>
      </visual>
      <!-- <collision> -->
      <!--   <origin xyz="0.225 0 0" rpy="0 0 0" /> -->
      <!--   <geometry> -->
      <!--     <box size="0.6135 0.052 0.15" /> -->
      <!--   </geometry> -->
      <!-- </collision> -->
    </link>
    ### link${self} ###
    <xacro:friction link="link${self}" />

    <!-- dummy root link for KDL -->
    <xacro:if value="${self == 1}">
      <link name="root">
        <inertial>
          <origin xyz="0 0 0" rpy="0 0 0"/>
          <mass value="0.00001"/>
          <inertia
              ixx="0.000001" ixy="0.0" ixz="0.0"
              iyy="0.000001" iyz="0.0"
              izz="0.000001"/>
        </inertial>
      </link>
      <joint name="root_joint" type="fixed">
        <parent link="root"/>
        <child link="link${self}"/>
        <origin rpy="0 0 0" xyz="0 0 0"/>
        <axis xyz="0 0 1"/>
      </joint>
    </xacro:if>

    <!-- cylinder collision model  -->
    <xacro:if value="${baselink}">
      <link name="cylinder_collision">
        <inertial>
          <origin xyz="0 0 0" rpy="0 0 0"/>
          <mass value="0.00001"/>
          <inertia
              ixx="0.000001" ixy="0.0" ixz="0.0"
              iyy="0.000001" iyz="0.0"
              izz="0.000001"/>
        </inertial>
        <collision>
          <geometry>
            <cylinder radius="0.4" length="0.03"/>
          </geometry>
        </collision>
      </link>
      <joint name="cylinder_collision_joint" type="fixed">
        <parent link="link${self}"/>
        <child link="cylinder_collision"/>
        <origin rpy="0 0 0" xyz="0.262 0.153 0"/>
        <axis xyz="0 0 1"/>
      </joint>
      <xacro:large_friction link="cylinder_collision"/>
    </xacro:if>

    <!-- set the fcu frame -->
    <xacro:if value="${baselink}">
      <link name="fc">
        <inertial>
          <origin xyz="0 0 0" rpy="0 0 0"/>
          <mass value="0.00001"/>
          <inertia
              ixx="0.000001" ixy="0.0" ixz="0.0"
              iyy="0.000001" iyz="0.0"
              izz="0.000002"/>
        </inertial>
      </link>
      <joint name="fc_joint" type="fixed">
        <child link="fc" />
        <parent link="link${self}" />
        <origin rpy="0 0 0" xyz="0 0 0" />
        <axis xyz="0 0 1"/>
      </joint>
    </xacro:if>

    <!-- gimbal  -->
    <link name="gimbal_link${self}">
      <inertial>
        <origin xyz="0.00821058 -0.00000236 0.00688663" rpy="0 0 0" />
        <mass value="0.26319459" />
        <inertia
            ixx="0.00067258" iyy="0.00073909" izz="0.00025874"
            ixy="0.00000001" ixz="-0.00013588" iyz="0.00000004" />
      </inertial>
      <visual>
        <origin rpy="0 0 0" xyz="0 0 0"/>
        <geometry>
          <mesh filename="package://rolling/urdf/shelled/mesh/roll_gimbal_module.STL" scale="0.001 0.001 0.001"/>
        </geometry>
        <xacro:black/>
      </visual>
      <!-- <collision> -->
      <!--   <origin xyz="0 0 ${rotor_offset}" rpy="0 ${(self % 2 * 2 - 1) * rotor_tilt} 0" /> -->
      <!--   <geometry> -->
      <!--     <cylinder radius="0.1" length="0.05" /> -->
      <!--   </geometry> -->
      <!-- </collision> -->
    </link>

    ### joints ###
    #### link joint ####
    <xacro:unless value="${self == child}">
      <joint name="joint${self}" type="revolute" >
        <limit effort="10.0" lower="${-pi}" upper="${pi}" velocity="0.1"/>
        <origin xyz="0.52477 0 0" rpy="0 0 0" />
        <parent link="link${self}" />
        <child  link="link${child}" />
        <axis xyz="0 0 1"/>
        <dynamics damping="0.9" friction="0.05"/>
      </joint>
    </xacro:unless>

    #### gimbal joint ####
    <joint name="gimbal${self}" type="continuous" >
      <limit effort="3" lower="-3.14" upper="3.14" velocity="12.5"/>
      <parent link="link${self}"/>
      <child link="gimbal_link${self}"/>
      <origin xyz="${rotor_pos} 0 0" rpy="0 0 0" />
      <axis xyz="1 0 0"/>
      <dynamics damping="0.1" friction="0.0"/>
    </joint>

    #### rotor coord link (virtual) ####
    <link name="rotor_coord${self}">
      <inertial>
        <origin xyz="0 0 0" rpy="0 0 0"/>
        <mass value="0.00001"/>
        <inertia
            ixx="0.0001" ixy="0.0" ixz="0.0"
            iyy="0.0001" iyz="0.0"
            izz="0.0002"/>
      </inertial>
    </link>

    #### rotor parent link (virtual) ####
    <link name="rotor_parent${self}">
      <inertial>
        <origin xyz="0 0 0" rpy="0 0 0"/>
        <mass value="0.00001"/>
        <inertia
            ixx="0.0001" ixy="0.0" ixz="0.0"
            iyy="0.0001" iyz="0.0"
            izz="0.0002"/>
      </inertial>
    </link>

    #### thrust link (virtual) ####
    <link name="thrust${self}">
      <inertial>
        <origin xyz="0 0 0" rpy="0 0 0"/>
        <mass value="0.00001"/>
        <inertia
            ixx="0.000001" ixy="0.0" ixz="0.0"
            iyy="0.000001" iyz="0.0"
            izz="0.000002"/>
      </inertial>
    </link>
    <xacro:damping_factor link="thrust${self}" />

    #### rotor coord link joint (virtual) ####
    <joint name="gimbal_coord${self}" type="continuous">
      <limit effort="3" lower="${-pi/2}" upper="${pi/2}" velocity="12.5"/>
      <parent link="link${self}"/>
      <child link="rotor_coord${self}"/>
      <origin rpy="0 0 0" xyz="0.3 0 0"/>
      <axis xyz="0 1 0"/>
      <dynamics damping="0.1" friction="0.0"/>
    </joint>

    #### rotor parent link joint (virtual) ####
    <joint name="gimbal_parent${self}" type="continuous">
      <limit effort="3.0" lower="${-pi/2}" upper="${pi/2}" velocity="12.5"/>
      <parent link="gimbal_link${self}"/>
      <child link="rotor_parent${self}"/>
      <origin rpy="0 0 0" xyz="0 0 ${rotor_offset}"/> # TODO: update rotor position
      <axis xyz="0 1 0"/>
      <dynamics damping="0.1" friction="0.0"/>
    </joint>

    #### rotor joint (virtual) ####
    <joint name="rotor${self}" type="continuous">
      <limit effort="100.0" lower="${min_force}" upper="${max_force}" velocity="0.5"/>
      <parent link="rotor_parent${self}"/>
      <child link="thrust${self}"/>
      <origin rpy="0 0 0" xyz="0 0 0"/>
      <axis xyz="0 0 ${rotor_direction}"/>
    </joint>

    #### hardware interface ####
    <xacro:unless value="${self == child}">
      <transmission name="joint_tran${self}">
        <type>transmission_interface/SimpleTransmission</type>
        <joint name="joint${self}">
          <hardwareInterface>hardware_interface/EffortJointInterface</hardwareInterface>
        </joint>
        <actuator name="servo${self}">
          <hardwareInterface>hardware_interface/EffortJointInterface</hardwareInterface>
          <mechanicalReduction>1</mechanicalReduction>
        </actuator>
      </transmission>
    </xacro:unless>

    <transmission name="gimbal_coord_tran${self}">
      <type>transmission_interface/SimpleTransmission</type>
      <joint name="gimbal_coord${self}">
        <hardwareInterface>hardware_interface/EffortJointInterface</hardwareInterface>
      </joint>
      <actuator name="gimbal_coord${self}">
        <hardwareInterface>hardware_interface/EffortJointInterface</hardwareInterface>
        <mechanicalReduction>1</mechanicalReduction>
      </actuator>
    </transmission>

    <transmission name="gimbal_parent_tran${self}">
      <type>transmission_interface/SimpleTransmission</type>
      <joint name="gimbal_parent${self}">
        <hardwareInterface>hardware_interface/EffortJointInterface</hardwareInterface>
      </joint>
      <actuator name="gimbal_parent${self}">
        <hardwareInterface>hardware_interface/EffortJointInterface</hardwareInterface>
        <mechanicalReduction>1</mechanicalReduction>
      </actuator>
    </transmission>

    <transmission name="gimbal_tran${self}">
      <type>transmission_interface/SimpleTransmission</type>
      <joint name="gimbal${self}">
        <hardwareInterface>hardware_interface/EffortJointInterface</hardwareInterface>
      </joint>
      <actuator name="gimbal_servo${self}">
        <hardwareInterface>hardware_interface/EffortJointInterface</hardwareInterface>
        <mechanicalReduction>1</mechanicalReduction>
      </actuator>
    </transmission>

    <transmission name="rotor${self}_tran">
      <type>transmission_interface/SimpleTransmission</type>
      <joint name="rotor${self}">
        <hardwareInterface>RotorInterface</hardwareInterface>
      </joint>
      <actuator name="rotor${self}">
        <hardwareInterface>RotorInterface</hardwareInterface>
        <mechanicalReduction>1</mechanicalReduction>
      </actuator>
    </transmission>

  </xacro:macro>

</robot>
