<?xml version="1.0"?>
<robot
    xmlns:xacro="http://www.ros.org/wiki/xacro" name="beetle_link" >

  <xacro:macro name="beetle_center_link" params="child1 child2 child3 child4">
    ## dummy
    <link name="root">
      <inertial>
        <origin xyz="0 0 0" rpy="0 0 0"/>
        <mass value="0.00001"/>
        <inertia
            ixx="0.000001" ixy="0.0" ixz="0.0"
            iyy="0.000001" iyz="0.0"
            izz="0.000001"/>
      </inertial>
    </link>
    <joint name="root_joint" type="fixed">
      <parent link="root"/>
      <child link="base_link"/>
      <origin rpy="0 0 0" xyz="0 0 0.099"/>
      <axis xyz="0 0 1"/>
    </joint>

    ## link
    <link name="base_link">
      <inertial>
        <origin xyz="0.00001050 0.00029063 0.00895728" rpy="0 0 0"/>
        <mass value="1.9614"/>
        <inertia
            ixx="0.01465916" iyy="0.01396881" izz="0.01999070"
            ixy="-0.00000632" ixz="0.00009113" iyz="0.00006625"/>
      </inertial>   
      <visual>
        <origin xyz="0 0 0" rpy="0 0 0"/>
        <geometry>
          <mesh filename="package://beetle/urdf/mesh/base_link_beetle_art_omni.dae"/>
        </geometry>
      </visual>
      <collision>
        <origin xyz="0 0 0.0385" rpy="0 0 0"/>
        <geometry>
          <box size="0.35 0.35 0.275"/>
        </geometry>
      </collision>
    </link>

    <xacro:damping_factor link="base_link"/>

    <link name="fc">
      <inertial>
        <origin xyz="0 0 0" rpy="0 0 0"/>
        <mass value="0.00001"/>
        <inertia
            ixx="0.000001" ixy="0.0" ixz="0.0"
            iyy="0.000001" iyz="0.0"
            izz="0.000001"/>
      </inertial>
    </link>
    <joint name="fc_joint" type="fixed">
      <child link="fc"/>
      <parent link="base_link"/>
      <origin rpy="0 0 0" xyz="-0.0175 -0.0015 0.06647"/>  # should be aligned with the position of IMU
      <axis xyz="0 0 1"/>
    </joint>

    ## rotor arm macro
    <xacro:macro name="dummy_rotor_arm" params="id x y z yaw">
      ## link
      <link name="rotor_arm${id}">
        <inertial>
          <origin xyz="0 0 0" rpy="0 0 0"/>
          <mass value="0.0001"/>
          <inertia
              ixx="0.000001" ixy="0.0" ixz="0.0"
              iyy="0.0001" iyz="0.0"
              izz="0.0001"/>
        </inertial>
      </link>
      ## joint
      <joint name="base_arm_joint${id}" type="fixed">
        <parent link="base_link"/>
        <child link="rotor_arm${id}"/>
        <origin rpy="0 0 ${yaw}" xyz="${x} ${y} ${z}"/>
        <axis xyz="0 0 1"/>
      </joint>
    </xacro:macro>

    ## dummy rotor arms
    <xacro:dummy_rotor_arm id = "${child1}" x = "0.17938" y="0.17938" z = "0.0171" yaw = "${pi*1.0/4.0}"/>
    <xacro:dummy_rotor_arm id = "${child2}" x = "-0.17938" y="0.17938" z = "0.0171" yaw = "${pi*3.0/4.0}"/>
    <xacro:dummy_rotor_arm id = "${child3}" x = "-0.17938" y="-0.17938" z = "0.0171" yaw = "${pi*5.0/4.0}"/>
    <xacro:dummy_rotor_arm id = "${child4}" x = "0.17938" y="-0.17938" z = "0.0171" yaw = "${-pi*1.0/4.0}"/>

    ## dummy link for the contact point coordinate
    <link name="contact_point">
      <inertial>
        <origin xyz="0 0 0" rpy="0 0 0"/>
        <mass value="0.0001"/>
        <inertia
                ixx="0.000001" ixy="0.0" ixz="0.0"
                iyy="0.0001" iyz="0.0"
                izz="0.0001"/>
      </inertial>
    </link>
    <joint name="cp_base_joint" type="fixed">
      <parent link="base_link"/>
      <child link="contact_point"/>
      <origin rpy="0 0 0" xyz="0.26 0 0"/>
      <axis xyz="0 0 1"/>
    </joint>

    <xacro:friction self="base_link"/>
  </xacro:macro>

  <xacro:macro name="beetle_thrust_link" params="self rotor_direction">
    ## link
    #### rotor parent link (virtual) ####
    <link name="gimbal_link${self}">
      <inertial>
        <origin xyz="0.02085225 0.0 -0.01276312" rpy="0 0 0"/>
        <mass value="0.15944"/>
        <inertia
            ixx="0.00007281" iyy="0.00007289" izz="0.00007635"
            ixy="0.0" ixz="0.0" iyz="0.0"/>
      </inertial>
      <collision>
        <origin xyz="0.06 0 0" rpy="0 0 0"/>
        <geometry>
          <box size="0.11 0.11 0.05"/>
        </geometry>
      </collision>
      <visual>
        <origin xyz="0 0 0" rpy="0 0 0"/>
        <geometry>
          <mesh filename="package://beetle/urdf/mesh/omni_rotor_module.dae"/>
        </geometry>
      </visual>
    </link>
    <xacro:damping_factor link="gimbal_link${self}"/>

    ## rotor parent link (virtual)
    <link name="rotor_parent${self}">
      <inertial>
        <origin xyz="0 0 0" rpy="0 0 0"/>
        <mass value="0.00001"/>
        <inertia
            ixx="0.000001" ixy="0.0" ixz="0.0"
            iyy="0.000001" iyz="0.0"
            izz="0.000001"/>
      </inertial>
    </link>

    ## thrust link (virtual)
    <link name="thrust${self}">
      <inertial>      
        <origin xyz="0 0 0" rpy="0 0 0"/>
        <mass value="0.005"/>
        <inertia
            ixx="0.001" ixy="0.0" ixz="0.0"
            iyy="0.001" iyz="0.0"
            izz="0.001"/>
      </inertial>
    </link>
    <xacro:damping_factor link="thrust${self}"/>

    #### joints ####

    #### gimbal joints ####
    <joint name="gimbal${self}" type="revolute">
      <limit effort="6.6" lower="-3.141593" upper="3.141593" velocity="3.0"/>
      <parent link="rotor_arm${self}"/>
      <child link="gimbal_link${self}"/>
      <origin rpy="0 0 0" xyz="0 0 0"/>
      <axis xyz="1 0 0"/>
      <dynamics damping="0.8" friction="0.0"/>
    </joint>

    <transmission name="joint_tran${self}">3.141593
      <type>transmission_interface/SimpleTransmission</type>
      <joint name="gimbal${self}">
        <hardwareInterface>hardware_interface/EffortJointInterface</hardwareInterface>
      </joint>
      <actuator name="servo${self}">
        <hardwareInterface>hardware_interface/EffortJointInterface</hardwareInterface>
        <mechanicalReduction>1</mechanicalReduction>
      </actuator>
    </transmission>
    #### rotor parent link joint (virtual) ####
    <joint name="rotor_parent_link_joint${self}" type="fixed">
      <parent link="gimbal_link${self}"/>
      <child link="rotor_parent${self}"/>
      <origin rpy="0 0 0" xyz="0.02185 0.0 0.0"/>
      <axis xyz="0 0 ${rotor_direction}"/>
    </joint>

    #### rotor joint (virtual) ####
    <joint name="rotor${self}" type="continuous">
      <limit effort="100.0" lower="${min_force}" upper="${max_force}" velocity="0.5"/>
      <parent link="rotor_parent${self}"/>
      <child link="thrust${self}"/>
      <origin rpy="0 0 0" xyz="0 0 0"/>
      <axis xyz="0 0 ${rotor_direction}"/>
    </joint>

    <transmission name="rotor_tran${self}">
      <type>transmission_interface/SimpleTransmission</type>
      <joint name="rotor${self}">
        <hardwareInterface>RotorInterface</hardwareInterface>
      </joint>
      <actuator name="rotor_actuator${self}">
        <hardwareInterface>RotorInterface</hardwareInterface>
        <mechanicalReduction>1</mechanicalReduction>
      </actuator>
    </transmission>

  </xacro:macro>
</robot>
