<?xml version="1.0" ?>
<robot name="hugmy">
  <!-- general attribute -->
  <baselink name="fc"/>
  <thrust_link name="thrust"/>
  <!-- dynamics -->
  <m_f_rate value="-0.0068"/>
  <!-- [N] -->
  <!-- dummy root link for KDL -->
  <link name="root">
    <inertial>
      <origin rpy="0 0 0" xyz="0 0 0"/>
      <mass value="0.00001"/>
      <inertia ixx="0.000001" ixy="0.0" ixz="0.0" iyy="0.000001" iyz="0.0" izz="0.000002"/>
    </inertial>
  </link>
  <joint name="root_joint" type="fixed">
    <parent link="root"/>
    <child link="main_body"/>
    <origin rpy="0 0 0" xyz="0 0 0"/>
    <axis xyz="0 0 1"/>
  </joint>
  <!-- main_body -->
  <link name="main_body">
    <inertial>
      <mass value="0.698"/>
      <origin rpy="0 0 0" xyz="0.00110883 0.00011825 0.00012320"/>
      <inertia ixx="0.00145773" ixy="-0.00000588" ixz="0.00002143" iyy="0.00150029" iyz="-0.00004262" izz="0.00061796"/>
    </inertial>
    <visual>
      <origin rpy="0 0 0" xyz="0 0 0"/>
      <geometry>
        <mesh filename="package://hugmy/urdf/mesh/Inflatable_asm.STL"/>
      </geometry>
    </visual>
    <collision>
      <origin rpy="0 0 0" xyz="0 0 0"/>
      <geometry>
        <box size="0.28 0.28 0.072"/>
      </geometry>
    </collision>
  </link>
  <!--link-->
  <link name="link_1_1">
    <inertial>
      <origin rpy="0 0 0" xyz="0.01174501 0.01750000 0.00608468"/>
      <mass value="0.00752930"/>
      <inertia ixx="0.00000411" ixy="0.00000155" ixz="0.00000051" iyy="0.00000214" iyz="0.00000080" izz="0.00000483"/>
    </inertial>
    <visual>
      <origin rpy="0 0 0" xyz="0 0 0"/>
      <geometry>
        <mesh filename="package://hugmy/urdf/mesh/cable_carrier_normal.dae"/>
      </geometry>
    </visual>
  </link>
  <link name="link_2_1">
    <inertial>
      <origin rpy="0 0 0" xyz="0.01174501 0.01750000 0.00608468"/>
      <mass value="0.00752930"/>
      <inertia ixx="0.00000411" ixy="0.00000155" ixz="0.00000051" iyy="0.00000214" iyz="0.00000080" izz="0.00000483"/>
    </inertial>
    <visual>
      <origin rpy="0 0 0" xyz="0 0 0"/>
      <geometry>
        <mesh filename="package://hugmy/urdf/mesh/cable_carrier_normal.dae"/>
      </geometry>
    </visual>
  </link>
  <link name="link_rotor_1">
    <inertial>
      <origin rpy="0 0 0" xyz="0.02005067 0.01755833 0.04034797"/>
      <mass value="0.11565729"/>
      <inertia ixx="0.00042229" ixy="0.00004075" ixz="0.00009327" iyy="0.00043336" iyz="0.00008185" izz="0.00034957"/>
    </inertial>
    <visual>
      <origin rpy="0 0 0" xyz="0 0 0"/>
      <geometry>
        <mesh filename="package://hugmy/urdf/mesh/long_cabble_carrier_and_moter_mount.STL"/>
      </geometry>
    </visual>
  </link>
  <link name="link_4_1">
    <inertial>
      <origin rpy="0 0 0" xyz="0.01174501 0.01750000 0.00608468"/>
      <mass value="0.00752930"/>
      <inertia ixx="0.00000411" ixy="0.00000155" ixz="0.00000051" iyy="0.00000214" iyz="0.00000080" izz="0.00000483"/>
    </inertial>
    <visual>
      <origin rpy="0 0 0" xyz="0 0 0"/>
      <geometry>
        <mesh filename="package://hugmy/urdf/mesh/cable_carrier_normal.dae"/>
      </geometry>
    </visual>
  </link>
  <link name="link_end_1">
    <inertial>
      <origin rpy="0 0 0" xyz="0.00910088 0.01750002 0.00845133"/>
      <mass value="0.00505969"/>
      <inertia ixx="0.00000287" ixy="0.00000081" ixz="0.00000044" iyy="0.00000126" iyz="0.00000075" izz="0.00000283"/>
    </inertial>
    <visual>
      <origin rpy="0 0 0" xyz="0 0 0"/>
      <geometry>
        <mesh filename="package://hugmy/urdf/mesh/cable_carrier_end.dae"/>
      </geometry>
    </visual>
  </link>
  <!-- joint -->
  <joint name="joint_1_1" type="revolute">
    <parent link="main_body"/>
    <child link="link_1_1"/>
    <origin rpy="0 0 6.283185307179586" xyz="0.05391 -0.0175 -0.039"/>
    <axis xyz="0 1 0"/>
    <limit effort="10" lower="0" upper="0.8727" velocity="1.0"/>
  </joint>
  <joint name="joint_2_1" type="revolute">
    <parent link="link_1_1"/>
    <child link="link_2_1"/>
    <origin rpy="0 0 0" xyz="0.023 0.00 0.00"/>
    <axis xyz="0 1 0"/>
    <limit effort="10" lower="0" upper="1.047" velocity="1.0"/>
  </joint>
  <joint name="joint_3_1" type="revolute">
    <parent link="link_2_1"/>
    <child link="link_rotor_1"/>
    <origin rpy="0 0 0" xyz="0.023 0.00 0.00"/>
    <axis xyz="0 1 0"/>
    <limit effort="10" lower="0" upper="1.047" velocity="1.0"/>
  </joint>
  <joint name="joint_4_1" type="revolute">
    <parent link="link_rotor_1"/>
    <child link="link_4_1"/>
    <origin rpy="0 0 0" xyz="0.04 0.00 0.00"/>
    <axis xyz="0 1 0"/>
    <limit effort="10" lower="0" upper="1.047" velocity="1.0"/>
  </joint>
  <joint name="joint_5_1" type="revolute">
    <parent link="link_4_1"/>
    <child link="link_end_1"/>
    <origin rpy="0 0 0" xyz="0.023 0.00 0.00"/>
    <axis xyz="0 1 0"/>
    <limit effort="10" lower="0" upper="1.047" velocity="1.0"/>
  </joint>
  <!--link-->
  <link name="link_1_2">
    <inertial>
      <origin rpy="0 0 0" xyz="0.01174501 0.01750000 0.00608468"/>
      <mass value="0.00752930"/>
      <inertia ixx="0.00000411" ixy="0.00000155" ixz="0.00000051" iyy="0.00000214" iyz="0.00000080" izz="0.00000483"/>
    </inertial>
    <visual>
      <origin rpy="0 0 0" xyz="0 0 0"/>
      <geometry>
        <mesh filename="package://hugmy/urdf/mesh/cable_carrier_normal.dae"/>
      </geometry>
    </visual>
  </link>
  <link name="link_2_2">
    <inertial>
      <origin rpy="0 0 0" xyz="0.01174501 0.01750000 0.00608468"/>
      <mass value="0.00752930"/>
      <inertia ixx="0.00000411" ixy="0.00000155" ixz="0.00000051" iyy="0.00000214" iyz="0.00000080" izz="0.00000483"/>
    </inertial>
    <visual>
      <origin rpy="0 0 0" xyz="0 0 0"/>
      <geometry>
        <mesh filename="package://hugmy/urdf/mesh/cable_carrier_normal.dae"/>
      </geometry>
    </visual>
  </link>
  <link name="link_rotor_2">
    <inertial>
      <origin rpy="0 0 0" xyz="0.02005067 0.01755833 0.04034797"/>
      <mass value="0.11565729"/>
      <inertia ixx="0.00042229" ixy="0.00004075" ixz="0.00009327" iyy="0.00043336" iyz="0.00008185" izz="0.00034957"/>
    </inertial>
    <visual>
      <origin rpy="0 0 0" xyz="0 0 0"/>
      <geometry>
        <mesh filename="package://hugmy/urdf/mesh/long_cabble_carrier_and_moter_mount.STL"/>
      </geometry>
    </visual>
  </link>
  <link name="link_4_2">
    <inertial>
      <origin rpy="0 0 0" xyz="0.01174501 0.01750000 0.00608468"/>
      <mass value="0.00752930"/>
      <inertia ixx="0.00000411" ixy="0.00000155" ixz="0.00000051" iyy="0.00000214" iyz="0.00000080" izz="0.00000483"/>
    </inertial>
    <visual>
      <origin rpy="0 0 0" xyz="0 0 0"/>
      <geometry>
        <mesh filename="package://hugmy/urdf/mesh/cable_carrier_normal.dae"/>
      </geometry>
    </visual>
  </link>
  <link name="link_end_2">
    <inertial>
      <origin rpy="0 0 0" xyz="0.00910088 0.01750002 0.00845133"/>
      <mass value="0.00505969"/>
      <inertia ixx="0.00000287" ixy="0.00000081" ixz="0.00000044" iyy="0.00000126" iyz="0.00000075" izz="0.00000283"/>
    </inertial>
    <visual>
      <origin rpy="0 0 0" xyz="0 0 0"/>
      <geometry>
        <mesh filename="package://hugmy/urdf/mesh/cable_carrier_end.dae"/>
      </geometry>
    </visual>
  </link>
  <!-- joint -->
  <joint name="joint_1_2" type="revolute">
    <parent link="main_body"/>
    <child link="link_1_2"/>
    <origin rpy="0 0 7.853981633974483" xyz="0.0175 0.05391 -0.039"/>
    <axis xyz="0 1 0"/>
    <limit effort="10" lower="0" upper="0.8727" velocity="1.0"/>
  </joint>
  <joint name="joint_2_2" type="revolute">
    <parent link="link_1_2"/>
    <child link="link_2_2"/>
    <origin rpy="0 0 0" xyz="0.023 0.00 0.00"/>
    <axis xyz="0 1 0"/>
    <limit effort="10" lower="0" upper="1.047" velocity="1.0"/>
  </joint>
  <joint name="joint_3_2" type="revolute">
    <parent link="link_2_2"/>
    <child link="link_rotor_2"/>
    <origin rpy="0 0 0" xyz="0.023 0.00 0.00"/>
    <axis xyz="0 1 0"/>
    <limit effort="10" lower="0" upper="1.047" velocity="1.0"/>
  </joint>
  <joint name="joint_4_2" type="revolute">
    <parent link="link_rotor_2"/>
    <child link="link_4_2"/>
    <origin rpy="0 0 0" xyz="0.04 0.00 0.00"/>
    <axis xyz="0 1 0"/>
    <limit effort="10" lower="0" upper="1.047" velocity="1.0"/>
  </joint>
  <joint name="joint_5_2" type="revolute">
    <parent link="link_4_2"/>
    <child link="link_end_2"/>
    <origin rpy="0 0 0" xyz="0.023 0.00 0.00"/>
    <axis xyz="0 1 0"/>
    <limit effort="10" lower="0" upper="1.047" velocity="1.0"/>
  </joint>
  <!--link-->
  <link name="link_1_3">
    <inertial>
      <origin rpy="0 0 0" xyz="0.01174501 0.01750000 0.00608468"/>
      <mass value="0.00752930"/>
      <inertia ixx="0.00000411" ixy="0.00000155" ixz="0.00000051" iyy="0.00000214" iyz="0.00000080" izz="0.00000483"/>
    </inertial>
    <visual>
      <origin rpy="0 0 0" xyz="0 0 0"/>
      <geometry>
        <mesh filename="package://hugmy/urdf/mesh/cable_carrier_normal.dae"/>
      </geometry>
    </visual>
  </link>
  <link name="link_2_3">
    <inertial>
      <origin rpy="0 0 0" xyz="0.01174501 0.01750000 0.00608468"/>
      <mass value="0.00752930"/>
      <inertia ixx="0.00000411" ixy="0.00000155" ixz="0.00000051" iyy="0.00000214" iyz="0.00000080" izz="0.00000483"/>
    </inertial>
    <visual>
      <origin rpy="0 0 0" xyz="0 0 0"/>
      <geometry>
        <mesh filename="package://hugmy/urdf/mesh/cable_carrier_normal.dae"/>
      </geometry>
    </visual>
  </link>
  <link name="link_rotor_3">
    <inertial>
      <origin rpy="0 0 0" xyz="0.02005067 0.01755833 0.04034797"/>
      <mass value="0.11565729"/>
      <inertia ixx="0.00042229" ixy="0.00004075" ixz="0.00009327" iyy="0.00043336" iyz="0.00008185" izz="0.00034957"/>
    </inertial>
    <visual>
      <origin rpy="0 0 0" xyz="0 0 0"/>
      <geometry>
        <mesh filename="package://hugmy/urdf/mesh/long_cabble_carrier_and_moter_mount.STL"/>
      </geometry>
    </visual>
  </link>
  <link name="link_4_3">
    <inertial>
      <origin rpy="0 0 0" xyz="0.01174501 0.01750000 0.00608468"/>
      <mass value="0.00752930"/>
      <inertia ixx="0.00000411" ixy="0.00000155" ixz="0.00000051" iyy="0.00000214" iyz="0.00000080" izz="0.00000483"/>
    </inertial>
    <visual>
      <origin rpy="0 0 0" xyz="0 0 0"/>
      <geometry>
        <mesh filename="package://hugmy/urdf/mesh/cable_carrier_normal.dae"/>
      </geometry>
    </visual>
  </link>
  <link name="link_end_3">
    <inertial>
      <origin rpy="0 0 0" xyz="0.00910088 0.01750002 0.00845133"/>
      <mass value="0.00505969"/>
      <inertia ixx="0.00000287" ixy="0.00000081" ixz="0.00000044" iyy="0.00000126" iyz="0.00000075" izz="0.00000283"/>
    </inertial>
    <visual>
      <origin rpy="0 0 0" xyz="0 0 0"/>
      <geometry>
        <mesh filename="package://hugmy/urdf/mesh/cable_carrier_end.dae"/>
      </geometry>
    </visual>
  </link>
  <!-- joint -->
  <joint name="joint_1_3" type="revolute">
    <parent link="main_body"/>
    <child link="link_1_3"/>
    <origin rpy="0 0 9.42477796076938" xyz="-0.05391 0.0175 -0.039"/>
    <axis xyz="0 1 0"/>
    <limit effort="10" lower="0" upper="0.8727" velocity="1.0"/>
  </joint>
  <joint name="joint_2_3" type="revolute">
    <parent link="link_1_3"/>
    <child link="link_2_3"/>
    <origin rpy="0 0 0" xyz="0.023 0.00 0.00"/>
    <axis xyz="0 1 0"/>
    <limit effort="10" lower="0" upper="1.047" velocity="1.0"/>
  </joint>
  <joint name="joint_3_3" type="revolute">
    <parent link="link_2_3"/>
    <child link="link_rotor_3"/>
    <origin rpy="0 0 0" xyz="0.023 0.00 0.00"/>
    <axis xyz="0 1 0"/>
    <limit effort="10" lower="0" upper="1.047" velocity="1.0"/>
  </joint>
  <joint name="joint_4_3" type="revolute">
    <parent link="link_rotor_3"/>
    <child link="link_4_3"/>
    <origin rpy="0 0 0" xyz="0.04 0.00 0.00"/>
    <axis xyz="0 1 0"/>
    <limit effort="10" lower="0" upper="1.047" velocity="1.0"/>
  </joint>
  <joint name="joint_5_3" type="revolute">
    <parent link="link_4_3"/>
    <child link="link_end_3"/>
    <origin rpy="0 0 0" xyz="0.023 0.00 0.00"/>
    <axis xyz="0 1 0"/>
    <limit effort="10" lower="0" upper="1.047" velocity="1.0"/>
  </joint>
  <!--link-->
  <link name="link_1_4">
    <inertial>
      <origin rpy="0 0 0" xyz="0.01174501 0.01750000 0.00608468"/>
      <mass value="0.00752930"/>
      <inertia ixx="0.00000411" ixy="0.00000155" ixz="0.00000051" iyy="0.00000214" iyz="0.00000080" izz="0.00000483"/>
    </inertial>
    <visual>
      <origin rpy="0 0 0" xyz="0 0 0"/>
      <geometry>
        <mesh filename="package://hugmy/urdf/mesh/cable_carrier_normal.dae"/>
      </geometry>
    </visual>
  </link>
  <link name="link_2_4">
    <inertial>
      <origin rpy="0 0 0" xyz="0.01174501 0.01750000 0.00608468"/>
      <mass value="0.00752930"/>
      <inertia ixx="0.00000411" ixy="0.00000155" ixz="0.00000051" iyy="0.00000214" iyz="0.00000080" izz="0.00000483"/>
    </inertial>
    <visual>
      <origin rpy="0 0 0" xyz="0 0 0"/>
      <geometry>
        <mesh filename="package://hugmy/urdf/mesh/cable_carrier_normal.dae"/>
      </geometry>
    </visual>
  </link>
  <link name="link_rotor_4">
    <inertial>
      <origin rpy="0 0 0" xyz="0.02005067 0.01755833 0.04034797"/>
      <mass value="0.11565729"/>
      <inertia ixx="0.00042229" ixy="0.00004075" ixz="0.00009327" iyy="0.00043336" iyz="0.00008185" izz="0.00034957"/>
    </inertial>
    <visual>
      <origin rpy="0 0 0" xyz="0 0 0"/>
      <geometry>
        <mesh filename="package://hugmy/urdf/mesh/long_cabble_carrier_and_moter_mount.STL"/>
      </geometry>
    </visual>
  </link>
  <link name="link_4_4">
    <inertial>
      <origin rpy="0 0 0" xyz="0.01174501 0.01750000 0.00608468"/>
      <mass value="0.00752930"/>
      <inertia ixx="0.00000411" ixy="0.00000155" ixz="0.00000051" iyy="0.00000214" iyz="0.00000080" izz="0.00000483"/>
    </inertial>
    <visual>
      <origin rpy="0 0 0" xyz="0 0 0"/>
      <geometry>
        <mesh filename="package://hugmy/urdf/mesh/cable_carrier_normal.dae"/>
      </geometry>
    </visual>
  </link>
  <link name="link_end_4">
    <inertial>
      <origin rpy="0 0 0" xyz="0.00910088 0.01750002 0.00845133"/>
      <mass value="0.00505969"/>
      <inertia ixx="0.00000287" ixy="0.00000081" ixz="0.00000044" iyy="0.00000126" iyz="0.00000075" izz="0.00000283"/>
    </inertial>
    <visual>
      <origin rpy="0 0 0" xyz="0 0 0"/>
      <geometry>
        <mesh filename="package://hugmy/urdf/mesh/cable_carrier_end.dae"/>
      </geometry>
    </visual>
  </link>
  <!-- joint -->
  <joint name="joint_1_4" type="revolute">
    <parent link="main_body"/>
    <child link="link_1_4"/>
    <origin rpy="0 0 10.995574287564276" xyz="-0.0175 -0.05391 -0.039"/>
    <axis xyz="0 1 0"/>
    <limit effort="10" lower="0" upper="0.8727" velocity="1.0"/>
  </joint>
  <joint name="joint_2_4" type="revolute">
    <parent link="link_1_4"/>
    <child link="link_2_4"/>
    <origin rpy="0 0 0" xyz="0.023 0.00 0.00"/>
    <axis xyz="0 1 0"/>
    <limit effort="10" lower="0" upper="1.047" velocity="1.0"/>
  </joint>
  <joint name="joint_3_4" type="revolute">
    <parent link="link_2_4"/>
    <child link="link_rotor_4"/>
    <origin rpy="0 0 0" xyz="0.023 0.00 0.00"/>
    <axis xyz="0 1 0"/>
    <limit effort="10" lower="0" upper="1.047" velocity="1.0"/>
  </joint>
  <joint name="joint_4_4" type="revolute">
    <parent link="link_rotor_4"/>
    <child link="link_4_4"/>
    <origin rpy="0 0 0" xyz="0.04 0.00 0.00"/>
    <axis xyz="0 1 0"/>
    <limit effort="10" lower="0" upper="1.047" velocity="1.0"/>
  </joint>
  <joint name="joint_5_4" type="revolute">
    <parent link="link_4_4"/>
    <child link="link_end_4"/>
    <origin rpy="0 0 0" xyz="0.023 0.00 0.00"/>
    <axis xyz="0 1 0"/>
    <limit effort="10" lower="0" upper="1.047" velocity="1.0"/>
  </joint>
  <joint name="main_body2fc" type="fixed">
    <parent link="main_body"/>
    <child link="fc"/>
    <origin rpy="0 0 0" xyz="0 0 0"/>
  </joint>
  <link name="fc">
    <inertial>
      <mass value="00"/>
      <origin rpy="0 0 0" xyz="0 0 0"/>
      <inertia ixx="0.0" ixy="0.0" ixz="0.0" iyy="0.0" iyz="0.0" izz="0.0"/>
    </inertial>
  </link>
  <joint name="main_body2battery" type="fixed">
    <parent link="main_body"/>
    <child link="battery"/>
    <origin rpy="0 0 0" xyz="0.0105 0 -0.012"/>
  </joint>
  <link name="battery">
    <inertial>
      <mass value="0.188"/>
      <origin rpy="0 0 0" xyz="0 0 0"/>
      <inertia ixx="0.0" ixy="0.0" ixz="0.0" iyy="0.0002" iyz="0.0" izz="0.0002"/>
    </inertial>
    <visual>
      <origin rpy="0 0 0" xyz="0 0 0"/>
      <geometry>
        <mesh filename="package://hugmy/urdf/mesh/turnigy_3S_2200mAh.dae" scale="1 1 1"/>
      </geometry>
    </visual>
  </link>
  <joint name="rotor1" type="continuous">
    <limit effort="100.0" lower="0.0" upper="8.0" velocity="0.5"/>
    <parent link="link_rotor_1"/>
    <child link="thrust1"/>
    <origin rpy="0 0 0" xyz="0.020 0.0175 0.0369"/>
    <!-- <origin rpy="0 0 0" xyz="${x} ${y} ${z}"/> -->
    <axis xyz="0 0 -1"/>
  </joint>
  <link name="thrust1">
    <!-- visual & collisiont -->
    <inertial>
      <origin rpy="0 0 0" xyz="0 0 0"/>
      <mass value="0.0091"/>
      <inertia ixx="0.00000807" ixy="0.0" ixz="0.0" iyy="0.00000807" iyz="0.0" izz="0.00001612"/>
    </inertial>
    <visual>
      <origin rpy="0 0 0" xyz="0 0 0"/>
      <geometry>
        <mesh filename="package://hugmy/urdf/mesh/prop_5inch.dae"/>
      </geometry>
    </visual>
  </link>
  <gazebo reference="main_body">
    <dampingFactor>0.00</dampingFactor>
  </gazebo>
  <transmission name="rotor_tran1">
    <type>transmission_interface/SimpleTransmission</type>
    <joint name="rotor1">
      <!-- TODO: effort is torque, maybe position is enough -->
      <hardwareInterface>RotorInterface</hardwareInterface>
    </joint>
    <actuator name="rotor1">
      <!-- TODO: effort is torque, maybe position is enough -->
      <hardwareInterface>RotorInterface</hardwareInterface>
      <mechanicalReduction>1</mechanicalReduction>
    </actuator>
  </transmission>
  <joint name="rotor2" type="continuous">
    <limit effort="100.0" lower="0.0" upper="8.0" velocity="0.5"/>
    <parent link="link_rotor_2"/>
    <child link="thrust2"/>
    <origin rpy="0 0 0" xyz="0.020 0.0175 0.0369"/>
    <!-- <origin rpy="0 0 0" xyz="${x} ${y} ${z}"/> -->
    <axis xyz="0 0 1"/>
  </joint>
  <link name="thrust2">
    <!-- visual & collisiont -->
    <inertial>
      <origin rpy="0 0 0" xyz="0 0 0"/>
      <mass value="0.0091"/>
      <inertia ixx="0.00000807" ixy="0.0" ixz="0.0" iyy="0.00000807" iyz="0.0" izz="0.00001612"/>
    </inertial>
    <visual>
      <origin rpy="0 0 0" xyz="0 0 0"/>
      <geometry>
        <mesh filename="package://hugmy/urdf/mesh/prop_5inch.dae"/>
      </geometry>
    </visual>
  </link>
  <gazebo reference="main_body">
    <dampingFactor>0.00</dampingFactor>
  </gazebo>
  <transmission name="rotor_tran2">
    <type>transmission_interface/SimpleTransmission</type>
    <joint name="rotor2">
      <!-- TODO: effort is torque, maybe position is enough -->
      <hardwareInterface>RotorInterface</hardwareInterface>
    </joint>
    <actuator name="rotor2">
      <!-- TODO: effort is torque, maybe position is enough -->
      <hardwareInterface>RotorInterface</hardwareInterface>
      <mechanicalReduction>1</mechanicalReduction>
    </actuator>
  </transmission>
  <joint name="rotor3" type="continuous">
    <limit effort="100.0" lower="0.0" upper="8.0" velocity="0.5"/>
    <parent link="link_rotor_3"/>
    <child link="thrust3"/>
    <origin rpy="0 0 0" xyz="0.020 0.0175 0.0369"/>
    <!-- <origin rpy="0 0 0" xyz="${x} ${y} ${z}"/> -->
    <axis xyz="0 0 -1"/>
  </joint>
  <link name="thrust3">
    <!-- visual & collisiont -->
    <inertial>
      <origin rpy="0 0 0" xyz="0 0 0"/>
      <mass value="0.0091"/>
      <inertia ixx="0.00000807" ixy="0.0" ixz="0.0" iyy="0.00000807" iyz="0.0" izz="0.00001612"/>
    </inertial>
    <visual>
      <origin rpy="0 0 0" xyz="0 0 0"/>
      <geometry>
        <mesh filename="package://hugmy/urdf/mesh/prop_5inch.dae"/>
      </geometry>
    </visual>
  </link>
  <gazebo reference="main_body">
    <dampingFactor>0.00</dampingFactor>
  </gazebo>
  <transmission name="rotor_tran3">
    <type>transmission_interface/SimpleTransmission</type>
    <joint name="rotor3">
      <!-- TODO: effort is torque, maybe position is enough -->
      <hardwareInterface>RotorInterface</hardwareInterface>
    </joint>
    <actuator name="rotor3">
      <!-- TODO: effort is torque, maybe position is enough -->
      <hardwareInterface>RotorInterface</hardwareInterface>
      <mechanicalReduction>1</mechanicalReduction>
    </actuator>
  </transmission>
  <joint name="rotor4" type="continuous">
    <limit effort="100.0" lower="0.0" upper="8.0" velocity="0.5"/>
    <parent link="link_rotor_4"/>
    <child link="thrust4"/>
    <origin rpy="0 0 0" xyz="0.020 0.0175 0.0369"/>
    <!-- <origin rpy="0 0 0" xyz="${x} ${y} ${z}"/> -->
    <axis xyz="0 0 1"/>
  </joint>
  <link name="thrust4">
    <!-- visual & collisiont -->
    <inertial>
      <origin rpy="0 0 0" xyz="0 0 0"/>
      <mass value="0.0091"/>
      <inertia ixx="0.00000807" ixy="0.0" ixz="0.0" iyy="0.00000807" iyz="0.0" izz="0.00001612"/>
    </inertial>
    <visual>
      <origin rpy="0 0 0" xyz="0 0 0"/>
      <geometry>
        <mesh filename="package://hugmy/urdf/mesh/prop_5inch.dae"/>
      </geometry>
    </visual>
  </link>
  <gazebo reference="main_body">
    <dampingFactor>0.00</dampingFactor>
  </gazebo>
  <transmission name="rotor_tran4">
    <type>transmission_interface/SimpleTransmission</type>
    <joint name="rotor4">
      <!-- TODO: effort is torque, maybe position is enough -->
      <hardwareInterface>RotorInterface</hardwareInterface>
    </joint>
    <actuator name="rotor4">
      <!-- TODO: effort is torque, maybe position is enough -->
      <hardwareInterface>RotorInterface</hardwareInterface>
      <mechanicalReduction>1</mechanicalReduction>
    </actuator>
  </transmission>
  <!-- propellers -->
  <!-- <xacro:propeller_module id = "1" x = "${-rotor_x}" y = "${-rotor_y}" z = "${rotor_z}" direction = "1" /> -->
  <!-- <xacro:propeller_module id = "2" x = "${rotor_x}" y = "${-rotor_y}" z = "${rotor_z}" direction = "-1" /> -->
  <!-- <xacro:propeller_module id = "3" x = "${rotor_x}" y = "${rotor_y}" z = "${rotor_z}" direction = "1" /> -->
  <!-- <xacro:propeller_module id = "4" x = "${-rotor_x}" y = "${rotor_y}" z = "${rotor_z}"  direction = "-1" /> -->
</robot>

